<?xml version="1.0"?>
<!-- GENERATED by arm_assembly.py (mate-composed) - do not hand-edit. -->
<robot name="micro_arm">
  <mujoco><compiler balanceinertia="true" discardvisual="false" fusestatic="false" meshdir="meshes"/></mujoco>
  <material name="link"> <color rgba="0.78 0.78 0.80 1"/></material>
  <material name="tool"> <color rgba="0.27 0.51 0.71 1"/></material>
  <link name="base_link">
    <visual><geometry><mesh filename="cyclo_cage.stl" scale="0.001 0.001 0.001"/></geometry><material name="link"/></visual>
    <inertial><origin xyz="-0.0000 0.0000 -0.0112"/><mass value="0.5000"/><inertia ixx="2.97e-04" iyy="2.97e-04" izz="4.09e-04" ixy="0" ixz="0" iyz="0"/></inertial>
  </link>

  <joint name="j1_yaw" type="revolute">
    <parent link="base_link"/><child link="mast_link"/>
    <origin xyz="0.00000 0.00000 0.00600" rpy="-3.14159 -0.00000 0.00000"/><axis xyz="0.0 -0.0 -1.0"/>
    <limit lower="-3.1416" upper="3.1416" effort="3.6" velocity="3.0"/>
    <dynamics damping="0.05"/>
  </joint>

  <link name="mast_link">
    <visual><geometry><mesh filename="angle_mount.stl" scale="0.001 0.001 0.001"/></geometry><material name="link"/></visual>
    <inertial><origin xyz="0.0207 0.0000 0.0227"/><mass value="0.4530"/><inertia ixx="2.27e-04" iyy="2.91e-04" izz="1.98e-04" ixy="0" ixz="0" iyz="0"/></inertial>
  </link>

  <joint name="j2_shoulder" type="revolute">
    <parent link="mast_link"/><child link="upper_arm_link"/>
    <origin xyz="0.02590 0.00000 0.04220" rpy="-3.14159 0.00000 1.57080"/><axis xyz="0.0 1.0 -0.0"/>
    <limit lower="-1.9200" upper="1.9200" effort="5.5" velocity="3.0"/>
    <dynamics damping="0.05"/>
  </joint>

  <link name="upper_arm_link">
    <visual><geometry><mesh filename="arm_upper.stl" scale="0.001 0.001 0.001"/></geometry><material name="link"/></visual>
    <inertial><origin xyz="0.0356 -0.0044 0.0000"/><mass value="0.3004"/><inertia ixx="7.09e-05" iyy="4.29e-04" izz="3.75e-04" ixy="0" ixz="0" iyz="0"/></inertial>
  </link>

  <joint name="j3_elbow" type="revolute">
    <parent link="upper_arm_link"/><child link="forearm_link"/>
    <origin xyz="0.07500 -0.01220 0.00000" rpy="-3.14159 0.00000 -3.14159"/><axis xyz="0.0 1.0 -0.0"/>
    <limit lower="-2.6200" upper="2.6200" effort="3.6" velocity="3.0"/>
    <dynamics damping="0.05"/>
  </joint>

  <link name="forearm_link">
    <visual><geometry><mesh filename="arm_fore.stl" scale="0.001 0.001 0.001"/></geometry><material name="link"/></visual>
    <inertial><origin xyz="0.0243 -0.0039 0.0000"/><mass value="0.1933"/><inertia ixx="4.56e-05" iyy="1.95e-04" izz="1.60e-04" ixy="0" ixz="0" iyz="0"/></inertial>
  </link>

  <joint name="j4_wrist_pitch" type="revolute">
    <parent link="forearm_link"/><child link="wrist_link"/>
    <origin xyz="0.05200 -0.00310 -0.00000" rpy="1.57080 -0.00000 0.00000"/><axis xyz="0.0 -0.0 -1.0"/>
    <limit lower="-1.9200" upper="1.9200" effort="1.32" velocity="3.0"/>
    <dynamics damping="0.05"/>
  </joint>

  <link name="wrist_link">
    <visual><geometry><mesh filename="angle_mount.stl" scale="0.001 0.001 0.001"/></geometry><material name="link"/></visual>
    <inertial><origin xyz="0.0207 0.0000 0.0227"/><mass value="0.2180"/><inertia ixx="1.09e-04" iyy="1.40e-04" izz="9.53e-05" ixy="0" ixz="0" iyz="0"/></inertial>
  </link>

  <joint name="j5_tool_roll" type="revolute">
    <parent link="wrist_link"/><child link="tool_link"/>
    <origin xyz="0.03500 0.00000 0.04220" rpy="0.00000 1.57080 0.00000"/><axis xyz="1.0 0.0 0.0"/>
    <limit lower="-3.1416" upper="3.1416" effort="1.32" velocity="3.0"/>
    <dynamics damping="0.03"/>
  </joint>

  <link name="tool_link">
    <visual><origin xyz="0.006 0 0" rpy="0 1.5708 0"/><geometry><cylinder radius="0.018" length="0.006"/></geometry><material name="link"/></visual>
    <visual><origin xyz="0.022 0 0"/><geometry><box size="0.022 0.05 0.026"/></geometry><material name="link"/></visual>
    <visual><origin xyz="0.05 0.019 0"/><geometry><box size="0.05 0.008 0.024"/></geometry><material name="tool"/></visual>
    <visual><origin xyz="0.05 -0.019 0"/><geometry><box size="0.05 0.008 0.024"/></geometry><material name="tool"/></visual>
    <inertial><origin xyz="0.03 0 0"/><mass value="0.2800"/><inertia ixx="2.0e-04" iyy="3.0e-04" izz="3.0e-04" ixy="0" ixz="0" iyz="0"/></inertial>
  </link>

  <joint name="tcp_fixed" type="fixed"><parent link="tool_link"/><child link="tcp_link"/><origin xyz="0.08 0 0"/></joint>
  <link name="tcp_link"><inertial><mass value="0.001"/><inertia ixx="1e-6" iyy="1e-6" izz="1e-6" ixy="0" ixz="0" iyz="0"/></inertial></link>
  <transmission name="tr_j1_yaw"><type>transmission_interface/SimpleTransmission</type>
    <joint name="j1_yaw"><hardwareInterface>hardware_interface/PositionJointInterface</hardwareInterface></joint>
    <actuator name="j1_yaw_act"><mechanicalReduction>20</mechanicalReduction></actuator></transmission>

  <transmission name="tr_j2_shoulder"><type>transmission_interface/SimpleTransmission</type>
    <joint name="j2_shoulder"><hardwareInterface>hardware_interface/PositionJointInterface</hardwareInterface></joint>
    <actuator name="j2_shoulder_act"><mechanicalReduction>20</mechanicalReduction></actuator></transmission>

  <transmission name="tr_j3_elbow"><type>transmission_interface/SimpleTransmission</type>
    <joint name="j3_elbow"><hardwareInterface>hardware_interface/PositionJointInterface</hardwareInterface></joint>
    <actuator name="j3_elbow_act"><mechanicalReduction>20</mechanicalReduction></actuator></transmission>

  <transmission name="tr_j4_wrist_pitch"><type>transmission_interface/SimpleTransmission</type>
    <joint name="j4_wrist_pitch"><hardwareInterface>hardware_interface/PositionJointInterface</hardwareInterface></joint>
    <actuator name="j4_wrist_pitch_act"><mechanicalReduction>20</mechanicalReduction></actuator></transmission>

  <transmission name="tr_j5_tool_roll"><type>transmission_interface/SimpleTransmission</type>
    <joint name="j5_tool_roll"><hardwareInterface>hardware_interface/PositionJointInterface</hardwareInterface></joint>
    <actuator name="j5_tool_roll_act"><mechanicalReduction>20</mechanicalReduction></actuator></transmission>

</robot>
