<?xml version="1.0"?>
<!-- ============================================================
     arm_trunk.urdf — 3-DOF cycloid trunk, real Cycloidal R20 drive + NEMA17
     steppers at each joint. Arm segments are FLAT PLATE members.

     R20 drive: round body (~63.5 dia) = OUTPUT (rotates), bolts to DISTAL
     segment; square NEMA motor plate = FIXED, bolts to PROXIMAL segment.
     Drive centered on the joint -> segments mount to opposite ends and are
     offset ~36mm so they clear. J2/J3 alternate side (+Y/-Y) so the arm
     zig-zags. Round mounting plates (orange) match the round output face.

     STEPPERS (dark, NEMA17 42.3 sq x 40mm) sit on the FIXED side behind each
     motor plate -> they stick out the motor side so clearances are visible.
     J1's motor points DOWN, housed in the base pedestal. Reach ~0.486 m.
     ============================================================ -->
<robot name="cycloid_trunk_r20">

  <mujoco>
    <compiler balanceinertia="true" discardvisual="false" fusestatic="false"
              meshdir="meshes"/>
  </mujoco>

  <material name="motor">  <color rgba="0.13 0.13 0.15 1"/></material>
  <material name="stepper"><color rgba="0.07 0.07 0.08 1"/></material>
  <material name="body">   <color rgba="0.48 0.51 0.55 1"/></material>
  <material name="micro">  <color rgba="0.40 0.46 0.56 1"/></material>
  <material name="plate">  <color rgba="0.85 0.45 0.10 1"/></material>
  <material name="link">   <color rgba="0.78 0.78 0.80 1"/></material>
  <material name="tool">   <color rgba="0.27 0.51 0.71 1"/></material>

  <!-- ===== base: pedestal housing J1 stepper + J1 motor plate (fixed) ===== -->
  <link name="base_link">
    <visual><origin xyz="0 0 0.0275"/>           <!-- base pedestal (houses J1 motor) -->
      <geometry><cylinder radius="0.045" length="0.055"/></geometry>
      <material name="motor"/></visual>
    <visual><origin xyz="0 0 0.055"/>            <!-- J1 motor plate + REAL stepper (in mesh), axis Z -->
      <geometry><mesh filename="r20_motor.stl" scale="0.001 0.001 0.001"/></geometry>
      <material name="motor"/></visual>
    <inertial><origin xyz="0 0 0.03"/><mass value="1.0"/>
      <inertia ixx="3e-3" iyy="3e-3" izz="3e-3" ixy="0" ixz="0" iyz="0"/></inertial>
  </link>

  <!-- ===== J1 base yaw (Z) ===== -->
  <joint name="j1_yaw" type="revolute">
    <parent link="base_link"/><child link="mast_link"/>
    <origin xyz="0 0 0.073"/><axis xyz="0 0 1"/>
    <limit lower="-3.1416" upper="3.1416" effort="20" velocity="3.0"/>
    <dynamics damping="0.05"/>
  </joint>

  <link name="mast_link">
    <visual><origin xyz="0 0 -0.018"/>           <!-- J1 OUTPUT body (rotates), axis Z -->
      <geometry><mesh filename="r20_body.stl" scale="0.001 0.001 0.001"/></geometry>
      <material name="body"/></visual>
    <visual><origin xyz="0 0 0.0184"/>           <!-- J1 round output plate -->
      <geometry><cylinder radius="0.0315" length="0.005"/></geometry>
      <material name="plate"/></visual>
    <visual><origin xyz="0 -0.009 0.048"/>       <!-- mast: flat plate member -->
      <geometry><box size="0.055 0.012 0.060"/></geometry>
      <material name="link"/></visual>
    <visual><origin xyz="0 -0.018 0.078" rpy="-1.5708 0 0"/>  <!-- J2 motor plate (fixed), axis Y -->
      <geometry><mesh filename="r20_motor.stl" scale="0.001 0.001 0.001"/></geometry>
      <material name="motor"/></visual>
    <visual><origin xyz="0 -0.018 0.078" rpy="-1.5708 0 0"/>  <!-- J2 round motor plate -->
      <geometry><cylinder radius="0.0315" length="0.005"/></geometry>
      <material name="plate"/></visual>
    <inertial><origin xyz="0 0 0.04"/><mass value="0.6"/>
      <inertia ixx="1e-3" iyy="1e-3" izz="1e-3" ixy="0" ixz="0" iyz="0"/></inertial>
  </link>

  <!-- ===== J2 shoulder pitch (Y) ===== -->
  <joint name="j2_shoulder" type="revolute">
    <parent link="mast_link"/><child link="upper_arm_link"/>
    <origin xyz="0 0 0.078"/><axis xyz="0 1 0"/>
    <limit lower="-1.92" upper="1.92" effort="18" velocity="3.0"/>
    <dynamics damping="0.05"/>
  </joint>

  <link name="upper_arm_link">
    <visual><origin xyz="0 -0.018 0" rpy="-1.5708 0 0"/>     <!-- J2 OUTPUT body (+Y) -->
      <geometry><mesh filename="r20_body.stl" scale="0.001 0.001 0.001"/></geometry>
      <material name="body"/></visual>
    <visual><origin xyz="0 0.0184 0" rpy="-1.5708 0 0"/>     <!-- J2 round output plate -->
      <geometry><cylinder radius="0.0315" length="0.005"/></geometry>
      <material name="plate"/></visual>
    <visual><origin xyz="0 0.0184 0.105"/>                   <!-- upper arm: flat plate (+Y) -->
      <geometry><box size="0.050 0.010 0.210"/></geometry>
      <material name="link"/></visual>
    <visual><origin xyz="0 0.018 0.210" rpy="1.5708 0 0"/>   <!-- J3 motor plate (fixed, +Y) -->
      <geometry><mesh filename="r20_motor.stl" scale="0.001 0.001 0.001"/></geometry>
      <material name="motor"/></visual>
    <visual><origin xyz="0 0.018 0.210" rpy="1.5708 0 0"/>   <!-- J3 round motor plate -->
      <geometry><cylinder radius="0.0315" length="0.005"/></geometry>
      <material name="plate"/></visual>
    <inertial><origin xyz="0 0 0.105"/><mass value="0.5"/>
      <inertia ixx="2e-3" iyy="2e-3" izz="5e-4" ixy="0" ixz="0" iyz="0"/></inertial>
  </link>

  <!-- ===== J3 elbow pitch (Y) ===== -->
  <joint name="j3_elbow" type="revolute">
    <parent link="upper_arm_link"/><child link="forearm_link"/>
    <origin xyz="0 0 0.210"/><axis xyz="0 1 0"/>
    <limit lower="-2.62" upper="2.62" effort="15" velocity="3.0"/>
    <dynamics damping="0.05"/>
  </joint>

  <link name="forearm_link">
    <visual><origin xyz="0 0.018 0" rpy="1.5708 0 0"/>       <!-- J3 OUTPUT body (-Y) -->
      <geometry><mesh filename="r20_body.stl" scale="0.001 0.001 0.001"/></geometry>
      <material name="body"/></visual>
    <visual><origin xyz="0 -0.0184 0" rpy="1.5708 0 0"/>     <!-- J3 round output plate -->
      <geometry><cylinder radius="0.0315" length="0.005"/></geometry>
      <material name="plate"/></visual>
    <visual><origin xyz="0 -0.0184 0.075"/>                  <!-- forearm: flat plate (-Y) -->
      <geometry><box size="0.044 0.010 0.150"/></geometry>
      <material name="link"/></visual>
    <visual><origin xyz="0 -0.0314 0.162" rpy="-1.5708 0 0"/> <!-- J4 wrist-pitch Micro 20:1, axis Y -->
      <geometry><mesh filename="micro20.stl" scale="0.001 0.001 0.001"/></geometry>
      <material name="micro"/></visual>
    <visual><origin xyz="0 -0.0054 0.162" rpy="-1.5708 0 0"/> <!-- J4 micro output plate -->
      <geometry><cylinder radius="0.020" length="0.004"/></geometry>
      <material name="plate"/></visual>
    <inertial><origin xyz="0 0 0.09"/><mass value="0.35"/>
      <inertia ixx="2e-3" iyy="2e-3" izz="4e-4" ixy="0" ixz="0" iyz="0"/></inertial>
  </link>

  <!-- ===== J4 wrist pitch (Y) ===== -->
  <joint name="j4_wrist_pitch" type="revolute">
    <parent link="forearm_link"/><child link="wrist_link"/>
    <origin xyz="0 -0.0184 0.162"/><axis xyz="0 1 0"/>
    <limit lower="-1.92" upper="1.92" effort="6" velocity="3.0"/>
    <dynamics damping="0.03"/>
  </joint>

  <link name="wrist_link">
    <visual><origin xyz="0 -0.0184 0.025"/>                  <!-- wrist: short flat stub -->
      <geometry><box size="0.035 0.010 0.050"/></geometry>
      <material name="link"/></visual>
    <visual><origin xyz="0 -0.0184 0.037"/>                  <!-- J5 tool-roll Micro 20:1, axis Z -->
      <geometry><mesh filename="micro20.stl" scale="0.001 0.001 0.001"/></geometry>
      <material name="micro"/></visual>
    <visual><origin xyz="0 -0.0184 0.063"/>                  <!-- J5 micro output plate -->
      <geometry><cylinder radius="0.020" length="0.004"/></geometry>
      <material name="plate"/></visual>
    <inertial><origin xyz="0 -0.0184 0.03"/><mass value="0.15"/>
      <inertia ixx="3e-4" iyy="3e-4" izz="2e-4" ixy="0" ixz="0" iyz="0"/></inertial>
  </link>

  <!-- ===== J5 tool roll (Z) ===== -->
  <joint name="j5_tool_roll" type="revolute">
    <parent link="wrist_link"/><child link="tool_link"/>
    <origin xyz="0 -0.0184 0.050"/><axis xyz="0 0 1"/>
    <limit lower="-3.1416" upper="3.1416" effort="4" velocity="3.0"/>
    <dynamics damping="0.03"/>
  </joint>

  <link name="tool_link">
    <visual><origin xyz="0 0 0.018"/>                        <!-- tool flange -->
      <geometry><cylinder radius="0.020" length="0.006"/></geometry>
      <material name="plate"/></visual>
    <visual><origin xyz="0 0 0.048"/>                        <!-- tool stub -->
      <geometry><cylinder radius="0.006" length="0.060"/></geometry>
      <material name="tool"/></visual>
    <inertial><origin xyz="0 0 0.03"/><mass value="0.08"/>
      <inertia ixx="1e-4" iyy="1e-4" izz="5e-5" ixy="0" ixz="0" iyz="0"/></inertial>
  </link>

  <!-- ===== TCP ===== -->
  <joint name="tcp_fixed" type="fixed">
    <parent link="tool_link"/><child link="tcp_link"/>
    <origin xyz="0 0 0.078"/>
  </joint>
  <link name="tcp_link">
    <inertial><mass value="0.001"/>
      <inertia ixx="1e-6" iyy="1e-6" izz="1e-6" ixy="0" ixz="0" iyz="0"/></inertial>
  </link>

  <!-- ===== transmissions: where the per-joint reduction is recorded =====
       ROS-style <transmission> (ros2_control reads these; MuJoCo ignores them
       and gets its actuators from the sim scripts instead). mechanicalReduction
       = the drive ratio: R20 cycloidal = 20:1, 20:1 Micro at the wrist. Bump the
       load joints to 36 if you add the belt pre-stage (see sizing.py). -->
  <transmission name="tr_j1">
    <type>transmission_interface/SimpleTransmission</type>
    <joint name="j1_yaw"><hardwareInterface>hardware_interface/PositionJointInterface</hardwareInterface></joint>
    <actuator name="j1_motor"><mechanicalReduction>20</mechanicalReduction></actuator>
  </transmission>
  <transmission name="tr_j2">
    <type>transmission_interface/SimpleTransmission</type>
    <joint name="j2_shoulder"><hardwareInterface>hardware_interface/PositionJointInterface</hardwareInterface></joint>
    <actuator name="j2_motor"><mechanicalReduction>20</mechanicalReduction></actuator>
  </transmission>
  <transmission name="tr_j3">
    <type>transmission_interface/SimpleTransmission</type>
    <joint name="j3_elbow"><hardwareInterface>hardware_interface/PositionJointInterface</hardwareInterface></joint>
    <actuator name="j3_motor"><mechanicalReduction>20</mechanicalReduction></actuator>
  </transmission>
  <transmission name="tr_j4">
    <type>transmission_interface/SimpleTransmission</type>
    <joint name="j4_wrist_pitch"><hardwareInterface>hardware_interface/PositionJointInterface</hardwareInterface></joint>
    <actuator name="j4_motor"><mechanicalReduction>20</mechanicalReduction></actuator>
  </transmission>
  <transmission name="tr_j5">
    <type>transmission_interface/SimpleTransmission</type>
    <joint name="j5_tool_roll"><hardwareInterface>hardware_interface/PositionJointInterface</hardwareInterface></joint>
    <actuator name="j5_motor"><mechanicalReduction>20</mechanicalReduction></actuator>
  </transmission>

</robot>
